Workbook

Sheet Instruções
A1: Monitorização da Vacinação Sazonal — COVID-19 e Gripe
A2: Instruções de preenchimento (uma folha por concelho)
A4: 1. Preencher APENAS as células a amarelo. As células a cinzento contêm fórmulas e estão protegidas.
A5: 2. Cada linha corresponde a um estabelecimento. A coluna 'Tipologia' classifica-o como ERPI, CD (Centro de Dia), Lar Residencial ou UCCI — escolher da lista.
A6: 3. Para efeitos de totais, ERPI conta como 'ERPI' e todas as restantes tipologias (CD, Lar Residencial, UCCI) contam como 'Similares'.
A7: 4. 'Total Profissionais' e 'Total Utentes' referem-se ao total elegível do estabelecimento; 'aceitam' = aceitaram ser vacinados; 'vacinados' = efetivamente vacinados.
A8: 5. ATENÇÃO — profissionais partilhados: se a mesma instituição aparece em mais do que uma linha (ex.: ERPI e CD), os profissionais comuns devem ser contados apenas numa das linhas, para não duplicar os totais.
A9: 6. Novos estabelecimentos: usar as linhas em branco no fim da tabela (antes dos totais). Preencher a designação e a tipologia.
A10: 7. Uma célula fica a vermelho quando: falta a tipologia, ou o nº de vacinados/aceitantes excede o total respetivo — verificar o valor.
A11: 8. A folha 'Núcleo Vacinação' calcula-se automaticamente: não precisa de preenchimento.
A12: 9. As folhas estão protegidas sem palavra-passe (Rever > Desproteger folha, se necessário).
A14: Definições das colunas calculadas:
... A19: Exemplo de preenchimento (valores fictícios):
A20: Designação | B20: Tipologia | C20: Total Prof. | D20: Total Utentes | E20: Ut. aceitam (COVID) | F20: Ut. vacinados (COVID)
A21: Lar Exemplo de São Tomé (ERPI) | B21: ERPI | C21: 25 | D21: 60 | E21: 55 | F21: 52

Sheet Águeda
E1: COVID-19 | K1: GRIPE
A2: Designação do Estabelecimento | B2: Tipologia | C2: Total Profissionais | D2: Total Utentes | E2: Utentes aceitam | F2: Utentes vacinados | G2: % Utentes vacinados | H2: Profissionais aceitam | I2: Profissionais vacinados | J2: Total vacinados (U+P) | K2: Utentes aceitam | L2: Utentes vacinados | M2: % Utentes vacinados | N2: Profissionais aceitam | O2: Profissionais vacinados | P2: Total vacinados (U+P)
A3: Associação Fermentelense Assistência Crianças e 3ª Idade (ERPI) | B3: ERPI | G3: =IF($A3="","",IFERROR(F3/$D3,"")) | J3: =IF($A3="","",SUM(F3,I3)) -> 0 | M3: =IF($A3="","",IFERROR(L3/$D3,"")) | P3: =IF($A3="","",SUM(L3,O3)) -> 0
A4: Associação Macinhatense Recreio e Cultura "AMAR" (ERPI) | B4: ERPI | G4: =IF($A4="","",IFERROR(F4/$D4,"")) | J4: =IF($A4="","",SUM(F4,I4)) -> 0 | M4: =IF($A4="","",IFERROR(L4/$D4,"")) | P4: =IF($A4="","",SUM(L4,O4)) -> 0
A5: Centro Social de Belazaima do Chão (ERPI) | B5: ERPI | G5: =IF($A5="","",IFERROR(F5/$D5,"")) | J5: =IF($A5="","",SUM(F5,I5)) -> 0 | M5: =IF($A5="","",IFERROR(L5/$D5,"")) | P5: =IF($A5="","",SUM(L5,O5)) -> 0
A6: Jardim Social de Travassô (ERPI) | B6: ERPI | G6: =IF($A6="","",IFERROR(F6/$D6,"")) | J6: =IF($A6="","",SUM(F6,I6)) -> 0 | M6: =IF($A6="","",IFERROR(L6/$D6,"")) | P6: =IF($A6="","",SUM(L6,O6)) -> 0
A7: Centro Social Paroquial de Recardães - Cozinha 2 (ERPI) | B7: ERPI | G7: =IF($A7="","",IFERROR(F7/$D7,"")) | J7: =IF($A7="","",SUM(F7,I7)) -> 0 | M7: =IF($A7="","",IFERROR(L7/$D7,"")) | P7: =IF($A7="","",SUM(L7,O7)) -> 0
A8: Centro Social Paroquial de Recardães - Cozinha 1 (ERPI) | B8: ERPI | G8: =IF($A8="","",IFERROR(F8/$D8,"")) | J8: =IF($A8="","",SUM(F8,I8)) -> 0 | M8: =IF($A8="","",IFERROR(L8/$D8,"")) | P8: =IF($A8="","",SUM(L8,O8)) -> 0
A9: Fundação Nossa Senhora da Conceição de Valongo do Vouga (ERPI) | B9: ERPI | G9: =IF($A9="","",IFERROR(F9/$D9,"")) | J9: =IF($A9="","",SUM(F9,I9)) -> 0 | M9: =IF($A9="","",IFERROR(L9/$D9,"")) | P9: =IF($A9="","",SUM(L9,O9)) -> 0
A10: LAAC - Liga Amigos Aguada Cima (ERPI) | B10: ERPI | G10: =IF($A10="","",IFERROR(F10/$D10,"")) | J10: =IF($A10="","",SUM(F10,I10)) -> 0 | M10: =IF($A10="","",IFERROR(L10/$D10,"")) | P10: =IF($A10="","",SUM(L10,O10)) -> 0
A11: Associação Pais Mourisca Vouga "Os Pioneiros" (ERPI) | B11: ERPI | G11: =IF($A11="","",IFERROR(F11/$D11,"")) | J11: =IF($A11="","",SUM(F11,I11)) -> 0 | M11: =IF($A11="","",IFERROR(L11/$D11,"")) | P11: =IF($A11="","",SUM(L11,O11)) -> 0
A12: Centro Apoio Social Cultural e Recreativa "O Mágico " (ERPI) | B12: ERPI | G12: =IF($A12="","",IFERROR(F12/$D12,"")) | J12: =IF($A12="","",SUM(F12,I12)) -> 0 | M12: =IF($A12="","",IFERROR(L12/$D12,"")) | P12: =IF($A12="","",SUM(L12,O12)) -> 0
A13: Paraíso Social de Aguada De Baixo (ERPI) | B13: ERPI | G13: =IF($A13="","",IFERROR(F13/$D13,"")) | J13: =IF($A13="","",SUM(F13,I13)) -> 0 | M13: =IF($A13="","",IFERROR(L13/$D13,"")) | P13: =IF($A13="","",SUM(L13,O13)) -> 0
A14: Santa Casa da Misericórdia de Águeda - Lar Conde Sucena (ERPI) | B14: ERPI | G14: =IF($A14="","",IFERROR(F14/$D14,"")) | J14: =IF($A14="","",SUM(F14,I14)) -> 0 | M14: =IF($A14="","",IFERROR(L14/$D14,"")) | P14: =IF($A14="","",SUM(L14,O14)) -> 0
... A38: Santa Casa da Misericórdia de Águeda - Casa Repouso Dr. António Breda e Lea Breda (UCCI) | B38: UCCI | G38: =IF($A38="","",IFERROR(F38/$D38,"")) | J38: =IF($A38="","",SUM(F38,I38)) -> 0 | M38: =IF($A38="","",IFERROR(L38/$D38,"")) | P38: =IF($A38="","",SUM(L38,O38)) -> 0
G39: =IF($A39="","",IFERROR(F39/$D39,"")) | J39: =IF($A39="","",SUM(F39,I39)) | M39: =IF($A39="","",IFERROR(L39/$D39,"")) | P39: =IF($A39="","",SUM(L39,O39))
G40: =IF($A40="","",IFERROR(F40/$D40,"")) | J40: =IF($A40="","",SUM(F40,I40)) | M40: =IF($A40="","",IFERROR(L40/$D40,"")) | P40: =IF($A40="","",SUM(L40,O40))
G41: =IF($A41="","",IFERROR(F41/$D41,"")) | J41: =IF($A41="","",SUM(F41,I41)) | M41: =IF($A41="","",IFERROR(L41/$D41,"")) | P41: =IF($A41="","",SUM(L41,O41))
G42: =IF($A42="","",IFERROR(F42/$D42,"")) | J42: =IF($A42="","",SUM(F42,I42)) | M42: =IF($A42="","",IFERROR(L42/$D42,"")) | P42: =IF($A42="","",SUM(L42,O42))
A43: TOTAL ERPI | C43: =SUMIFS(C$3:C$42,$B$3:$B$42,"ERPI") -> 0 | D43: =SUMIFS(D$3:D$42,$B$3:$B$42,"ERPI") -> 0 | E43: =SUMIFS(E$3:E$42,$B$3:$B$42,"ERPI") -> 0 | F43: =SUMIFS(F$3:F$42,$B$3:$B$42,"ERPI") -> 0 | G43: =IFERROR(F43/D43,"") | H43: =SUMIFS(H$3:H$42,$B$3:$B$42,"ERPI") -> 0 | I43: =SUMIFS(I$3:I$42,$B$3:$B$42,"ERPI") -> 0 | J43: =SUM(F43,I43) -> 0 | K43: =SUMIFS(K$3:K$42,$B$3:$B$42,"ERPI") -> 0 | L43: =SUMIFS(L$3:L$42,$B$3:$B$42,"ERPI") -> 0 | M43: =IFERROR(L43/D43,"") | N43: =SUMIFS(N$3:N$42,$B$3:$B$42,"ERPI") -> 0 | O43: =SUMIFS(O$3:O$42,$B$3:$B$42,"ERPI") -> 0 | P43: =SUM(L43,O43) -> 0
A44: TOTAL SIMILARES | C44: =C45-C43 -> 0 | D44: =D45-D43 -> 0 | E44: =E45-E43 -> 0 | F44: =F45-F43 -> 0 | G44: =IFERROR(F44/D44,"") | H44: =H45-H43 -> 0 | I44: =I45-I43 -> 0 | J44: =SUM(F44,I44) -> 0 | K44: =K45-K43 -> 0 | L44: =L45-L43 -> 0 | M44: =IFERROR(L44/D44,"") | N44: =N45-N43 -> 0 | O44: =O45-O43 -> 0 | P44: =SUM(L44,O44) -> 0
A45: TOTAL CONCELHO | C45: =SUM(C$3:C$42) -> 0 | D45: =SUM(D$3:D$42) -> 0 | E45: =SUM(E$3:E$42) -> 0 | F45: =SUM(F$3:F$42) -> 0 | G45: =IFERROR(F45/D45,"") | H45: =SUM(H$3:H$42) -> 0 | I45: =SUM(I$3:I$42) -> 0 | J45: =SUM(F45,I45) -> 0 | K45: =SUM(K$3:K$42) -> 0 | L45: =SUM(L$3:L$42) -> 0 | M45: =IFERROR(L45/D45,"") | N45: =SUM(N$3:N$42) -> 0 | O45: =SUM(O$3:O$42) -> 0 | P45: =SUM(L45,O45) -> 0

Sheet Albergaria-A-Velha
E1: COVID-19 | K1: GRIPE
A2: Designação do Estabelecimento | B2: Tipologia | C2: Total Profissionais | D2: Total Utentes | E2: Utentes aceitam | F2: Utentes vacinados | G2: % Utentes vacinados | H2: Profissionais aceitam | I2: Profissionais vacinados | J2: Total vacinados (U+P) | K2: Utentes aceitam | L2: Utentes vacinados | M2: % Utentes vacinados | N2: Profissionais aceitam | O2: Profissionais vacinados | P2: Total vacinados (U+P)
A3: Sénior Vita Oliveiras (ERPI) | B3: ERPI | G3: =IF($A3="","",IFERROR(F3/$D3,"")) | J3: =IF($A3="","",SUM(F3,I3)) -> 0 | M3: =IF($A3="","",IFERROR(L3/$D3,"")) | P3: =IF($A3="","",SUM(L3,O3)) -> 0
A4: Associação Solidariedade Social Alquerubim (ERPI) | B4: ERPI | G4: =IF($A4="","",IFERROR(F4/$D4,"")) | J4: =IF($A4="","",SUM(F4,I4)) -> 0 | M4: =IF($A4="","",IFERROR(L4/$D4,"")) | P4: =IF($A4="","",SUM(L4,O4)) -> 0
A5: Solar das Camélias (ERPI) | B5: ERPI | G5: =IF($A5="","",IFERROR(F5/$D5,"")) | J5: =IF($A5="","",SUM(F5,I5)) -> 0 | M5: =IF($A5="","",IFERROR(L5/$D5,"")) | P5: =IF($A5="","",SUM(L5,O5)) -> 0
A6: Geriabranca (ERPI) | B6: ERPI | G6: =IF($A6="","",IFERROR(F6/$D6,"")) | J6: =IF($A6="","",SUM(F6,I6)) -> 0 | M6: =IF($A6="","",IFERROR(L6/$D6,"")) | P6: =IF($A6="","",SUM(L6,O6)) -> 0
A7: Irmandade da Misericórdia Albergaria-a-Velha (ERPI) | B7: ERPI | G7: =IF($A7="","",IFERROR(F7/$D7,"")) | J7: =IF($A7="","",SUM(F7,I7)) -> 0 | M7: =IF($A7="","",IFERROR(L7/$D7,"")) | P7: =IF($A7="","",SUM(L7,O7)) -> 0
A8: Residencias Montepio Albergaria (ERPI) | B8: ERPI | G8: =IF($A8="","",IFERROR(F8/$D8,"")) | J8: =IF($A8="","",SUM(F8,I8)) -> 0 | M8: =IF($A8="","",IFERROR(L8/$D8,"")) | P8: =IF($A8="","",SUM(L8,O8)) -> 0
A9: Associação Solidariedade Social Alquerubim (CD) | B9: CD | G9: =IF($A9="","",IFERROR(F9/$D9,"")) | J9: =IF($A9="","",SUM(F9,I9)) -> 0 | M9: =IF($A9="","",IFERROR(L9/$D9,"")) | P9: =IF($A9="","",SUM(L9,O9)) -> 0
A10: Irmandade da Misericórdia Albergaria-a-Velha (CD) | B10: CD | G10: =IF($A10="","",IFERROR(F10/$D10,"")) | J10: =IF($A10="","",SUM(F10,I10)) -> 0 | M10: =IF($A10="","",IFERROR(L10/$D10,"")) | P10: =IF($A10="","",SUM(L10,O10)) -> 0
A11: Centro Social e Paroquial de Angeja (CD) | B11: CD | G11: =IF($A11="","",IFERROR(F11/$D11,"")) | J11: =IF($A11="","",SUM(F11,I11)) -> 0 | M11: =IF($A11="","",IFERROR(L11/$D11,"")) | P11: =IF($A11="","",SUM(L11,O11)) -> 0
A12: Probranca - Centro Comunitário Padre Conde (CD) | B12: CD | G12: =IF($A12="","",IFERROR(F12/$D12,"")) | J12: =IF($A12="","",SUM(F12,I12)) -> 0 | M12: =IF($A12="","",IFERROR(L12/$D12,"")) | P12: =IF($A12="","",SUM(L12,O12)) -> 0
A13: CEDIARA - Associação de Solidariedade Social de Ribeira de Fráguas (CD) | B13: CD | G13: =IF($A13="","",IFERROR(F13/$D13,"")) | J13: =IF($A13="","",SUM(F13,I13)) -> 0 | M13: =IF($A13="","",IFERROR(L13/$D13,"")) | P13: =IF($A13="","",SUM(L13,O13)) -> 0
A14: APPACDM - Soutelo (Lar Residencial) | B14: Lar Residencial | G14: =IF($A14="","",IFERROR(F14/$D14,"")) | J14: =IF($A14="","",SUM(F14,I14)) -> 0 | M14: =IF($A14="","",IFERROR(L14/$D14,"")) | P14: =IF($A14="","",SUM(L14,O14)) -> 0
... A16: Residencias Montepio Albergaria (UCCI) | B16: UCCI | G16: =IF($A16="","",IFERROR(F16/$D16,"")) | J16: =IF($A16="","",SUM(F16,I16)) -> 0 | M16: =IF($A16="","",IFERROR(L16/$D16,"")) | P16: =IF($A16="","",SUM(L16,O16)) -> 0
G17: =IF($A17="","",IFERROR(F17/$D17,"")) | J17: =IF($A17="","",SUM(F17,I17)) | M17: =IF($A17="","",IFERROR(L17/$D17,"")) | P17: =IF($A17="","",SUM(L17,O17))
G18: =IF($A18="","",IFERROR(F18/$D18,"")) | J18: =IF($A18="","",SUM(F18,I18)) | M18: =IF($A18="","",IFERROR(L18/$D18,"")) | P18: =IF($A18="","",SUM(L18,O18))
G19: =IF($A19="","",IFERROR(F19/$D19,"")) | J19: =IF($A19="","",SUM(F19,I19)) | M19: =IF($A19="","",IFERROR(L19/$D19,"")) | P19: =IF($A19="","",SUM(L19,O19))
G20: =IF($A20="","",IFERROR(F20/$D20,"")) | J20: =IF($A20="","",SUM(F20,I20)) | M20: =IF($A20="","",IFERROR(L20/$D20,"")) | P20: =IF($A20="","",SUM(L20,O20))
A21: TOTAL ERPI | C21: =SUMIFS(C$3:C$20,$B$3:$B$20,"ERPI") -> 0 | D21: =SUMIFS(D$3:D$20,$B$3:$B$20,"ERPI") -> 0 | E21: =SUMIFS(E$3:E$20,$B$3:$B$20,"ERPI") -> 0 | F21: =SUMIFS(F$3:F$20,$B$3:$B$20,"ERPI") -> 0 | G21: =IFERROR(F21/D21,"") | H21: =SUMIFS(H$3:H$20,$B$3:$B$20,"ERPI") -> 0 | I21: =SUMIFS(I$3:I$20,$B$3:$B$20,"ERPI") -> 0 | J21: =SUM(F21,I21) -> 0 | K21: =SUMIFS(K$3:K$20,$B$3:$B$20,"ERPI") -> 0 | L21: =SUMIFS(L$3:L$20,$B$3:$B$20,"ERPI") -> 0 | M21: =IFERROR(L21/D21,"") | N21: =SUMIFS(N$3:N$20,$B$3:$B$20,"ERPI") -> 0 | O21: =SUMIFS(O$3:O$20,$B$3:$B$20,"ERPI") -> 0 | P21: =SUM(L21,O21) -> 0
A22: TOTAL SIMILARES | C22: =C23-C21 -> 0 | D22: =D23-D21 -> 0 | E22: =E23-E21 -> 0 | F22: =F23-F21 -> 0 | G22: =IFERROR(F22/D22,"") | H22: =H23-H21 -> 0 | I22: =I23-I21 -> 0 | J22: =SUM(F22,I22) -> 0 | K22: =K23-K21 -> 0 | L22: =L23-L21 -> 0 | M22: =IFERROR(L22/D22,"") | N22: =N23-N21 -> 0 | O22: =O23-O21 -> 0 | P22: =SUM(L22,O22) -> 0
A23: TOTAL CONCELHO | C23: =SUM(C$3:C$20) -> 0 | D23: =SUM(D$3:D$20) -> 0 | E23: =SUM(E$3:E$20) -> 0 | F23: =SUM(F$3:F$20) -> 0 | G23: =IFERROR(F23/D23,"") | H23: =SUM(H$3:H$20) -> 0 | I23: =SUM(I$3:I$20) -> 0 | J23: =SUM(F23,I23) -> 0 | K23: =SUM(K$3:K$20) -> 0 | L23: =SUM(L$3:L$20) -> 0 | M23: =IFERROR(L23/D23,"") | N23: =SUM(N$3:N$20) -> 0 | O23: =SUM(O$3:O$20) -> 0 | P23: =SUM(L23,O23) -> 0

Sheet Anadia
E1: COVID-19 | K1: GRIPE
A2: Designação do Estabelecimento | B2: Tipologia | C2: Total Profissionais | D2: Total Utentes | E2: Utentes aceitam | F2: Utentes vacinados | G2: % Utentes vacinados | H2: Profissionais aceitam | I2: Profissionais vacinados | J2: Total vacinados (U+P) | K2: Utentes aceitam | L2: Utentes vacinados | M2: % Utentes vacinados | N2: Profissionais aceitam | O2: Profissionais vacinados | P2: Total vacinados (U+P)
A3: ASAC -Associação Social de Avelãs de Caminho (ERPI) | B3: ERPI | G3: =IF($A3="","",IFERROR(F3/$D3,"")) | J3: =IF($A3="","",SUM(F3,I3)) -> 0 | M3: =IF($A3="","",IFERROR(L3/$D3,"")) | P3: =IF($A3="","",SUM(L3,O3)) -> 0
A4: Centro Social e Cultural Nossa Senhora do Ó de Aguim (ERPI) | B4: ERPI | G4: =IF($A4="","",IFERROR(F4/$D4,"")) | J4: =IF($A4="","",SUM(F4,I4)) -> 0 | M4: =IF($A4="","",IFERROR(L4/$D4,"")) | P4: =IF($A4="","",SUM(L4,O4)) -> 0
A5: Centro Social Paroquial da Moita de Anadia (ERPI) | B5: ERPI | G5: =IF($A5="","",IFERROR(F5/$D5,"")) | J5: =IF($A5="","",SUM(F5,I5)) -> 0 | M5: =IF($A5="","",IFERROR(L5/$D5,"")) | P5: =IF($A5="","",SUM(L5,O5)) -> 0
A6: Centro Social Cultural Recreativo de Poutena (erpi) | B6: ERPI | G6: =IF($A6="","",IFERROR(F6/$D6,"")) | J6: =IF($A6="","",SUM(F6,I6)) -> 0 | M6: =IF($A6="","",IFERROR(L6/$D6,"")) | P6: =IF($A6="","",SUM(L6,O6)) -> 0
A7: Centro Social Cultural e Recreativo da Freguesia de Avelãs Cima (ERPI) | B7: ERPI | G7: =IF($A7="","",IFERROR(F7/$D7,"")) | J7: =IF($A7="","",SUM(F7,I7)) -> 0 | M7: =IF($A7="","",IFERROR(L7/$D7,"")) | P7: =IF($A7="","",SUM(L7,O7)) -> 0
A8: Misericórdia de Sangalhos - Lar (ERPI) | B8: ERPI | G8: =IF($A8="","",IFERROR(F8/$D8,"")) | J8: =IF($A8="","",SUM(F8,I8)) -> 0 | M8: =IF($A8="","",IFERROR(L8/$D8,"")) | P8: =IF($A8="","",SUM(L8,O8)) -> 0
A9: Santa Casa da Misericórdia de Anadia - Complexo Social Seabra Castro (ERPI) | B9: ERPI | G9: =IF($A9="","",IFERROR(F9/$D9,"")) | J9: =IF($A9="","",SUM(F9,I9)) -> 0 | M9: =IF($A9="","",IFERROR(L9/$D9,"")) | P9: =IF($A9="","",SUM(L9,O9)) -> 0
A10: Santa Casa da Misericórdia de Anadia - Lar José Luciano de Castro (ERPI) | B10: ERPI | G10: =IF($A10="","",IFERROR(F10/$D10,"")) | J10: =IF($A10="","",SUM(F10,I10)) -> 0 | M10: =IF($A10="","",IFERROR(L10/$D10,"")) | P10: =IF($A10="","",SUM(L10,O10)) -> 0
A11: Ibervita - Residências Senior Assistidas (ERPI) | B11: ERPI | G11: =IF($A11="","",IFERROR(F11/$D11,"")) | J11: =IF($A11="","",SUM(F11,I11)) -> 0 | M11: =IF($A11="","",IFERROR(L11/$D11,"")) | P11: =IF($A11="","",SUM(L11,O11)) -> 0
A12: Hotel Sénior Curia (ERPI) | B12: ERPI | G12: =IF($A12="","",IFERROR(F12/$D12,"")) | J12: =IF($A12="","",SUM(F12,I12)) -> 0 | M12: =IF($A12="","",IFERROR(L12/$D12,"")) | P12: =IF($A12="","",SUM(L12,O12)) -> 0
A13: ASAC -Associação Social de Avelãs de Caminho (CD) | B13: CD | G13: =IF($A13="","",IFERROR(F13/$D13,"")) | J13: =IF($A13="","",SUM(F13,I13)) -> 0 | M13: =IF($A13="","",IFERROR(L13/$D13,"")) | P13: =IF($A13="","",SUM(L13,O13)) -> 0
A14: Centro Social e Cultural Nossa Senhora do Ó de Aguim (CD) | B14: CD | G14: =IF($A14="","",IFERROR(F14/$D14,"")) | J14: =IF($A14="","",SUM(F14,I14)) -> 0 | M14: =IF($A14="","",IFERROR(L14/$D14,"")) | P14: =IF($A14="","",SUM(L14,O14)) -> 0
... A28: Santa Casa da Misericórdia de Anadia - Hospital José Luciano Castro (UCCI) | B28: UCCI | G28: =IF($A28="","",IFERROR(F28/$D28,"")) | J28: =IF($A28="","",SUM(F28,I28)) -> 0 | M28: =IF($A28="","",IFERROR(L28/$D28,"")) | P28: =IF($A28="","",SUM(L28,O28)) -> 0
G29: =IF($A29="","",IFERROR(F29/$D29,"")) | J29: =IF($A29="","",SUM(F29,I29)) | M29: =IF($A29="","",IFERROR(L29/$D29,"")) | P29: =IF($A29="","",SUM(L29,O29))
G30: =IF($A30="","",IFERROR(F30/$D30,"")) | J30: =IF($A30="","",SUM(F30,I30)) | M30: =IF($A30="","",IFERROR(L30/$D30,"")) | P30: =IF($A30="","",SUM(L30,O30))
G31: =IF($A31="","",IFERROR(F31/$D31,"")) | J31: =IF($A31="","",SUM(F31,I31)) | M31: =IF($A31="","",IFERROR(L31/$D31,"")) | P31: =IF($A31="","",SUM(L31,O31))
G32: =IF($A32="","",IFERROR(F32/$D32,"")) | J32: =IF($A32="","",SUM(F32,I32)) | M32: =IF($A32="","",IFERROR(L32/$D32,"")) | P32: =IF($A32="","",SUM(L32,O32))
A33: TOTAL ERPI | C33: =SUMIFS(C$3:C$32,$B$3:$B$32,"ERPI") -> 0 | D33: =SUMIFS(D$3:D$32,$B$3:$B$32,"ERPI") -> 0 | E33: =SUMIFS(E$3:E$32,$B$3:$B$32,"ERPI") -> 0 | F33: =SUMIFS(F$3:F$32,$B$3:$B$32,"ERPI") -> 0 | G33: =IFERROR(F33/D33,"") | H33: =SUMIFS(H$3:H$32,$B$3:$B$32,"ERPI") -> 0 | I33: =SUMIFS(I$3:I$32,$B$3:$B$32,"ERPI") -> 0 | J33: =SUM(F33,I33) -> 0 | K33: =SUMIFS(K$3:K$32,$B$3:$B$32,"ERPI") -> 0 | L33: =SUMIFS(L$3:L$32,$B$3:$B$32,"ERPI") -> 0 | M33: =IFERROR(L33/D33,"") | N33: =SUMIFS(N$3:N$32,$B$3:$B$32,"ERPI") -> 0 | O33: =SUMIFS(O$3:O$32,$B$3:$B$32,"ERPI") -> 0 | P33: =SUM(L33,O33) -> 0
A34: TOTAL SIMILARES | C34: =C35-C33 -> 0 | D34: =D35-D33 -> 0 | E34: =E35-E33 -> 0 | F34: =F35-F33 -> 0 | G34: =IFERROR(F34/D34,"") | H34: =H35-H33 -> 0 | I34: =I35-I33 -> 0 | J34: =SUM(F34,I34) -> 0 | K34: =K35-K33 -> 0 | L34: =L35-L33 -> 0 | M34: =IFERROR(L34/D34,"") | N34: =N35-N33 -> 0 | O34: =O35-O33 -> 0 | P34: =SUM(L34,O34) -> 0
A35: TOTAL CONCELHO | C35: =SUM(C$3:C$32) -> 0 | D35: =SUM(D$3:D$32) -> 0 | E35: =SUM(E$3:E$32) -> 0 | F35: =SUM(F$3:F$32) -> 0 | G35: =IFERROR(F35/D35,"") | H35: =SUM(H$3:H$32) -> 0 | I35: =SUM(I$3:I$32) -> 0 | J35: =SUM(F35,I35) -> 0 | K35: =SUM(K$3:K$32) -> 0 | L35: =SUM(L$3:L$32) -> 0 | M35: =IFERROR(L35/D35,"") | N35: =SUM(N$3:N$32) -> 0 | O35: =SUM(O$3:O$32) -> 0 | P35: =SUM(L35,O35) -> 0

Sheet Aveiro
E1: COVID-19 | K1: GRIPE
A2: Designação do Estabelecimento | B2: Tipologia | C2: Total Profissionais | D2: Total Utentes | E2: Utentes aceitam | F2: Utentes vacinados | G2: % Utentes vacinados | H2: Profissionais aceitam | I2: Profissionais vacinados | J2: Total vacinados (U+P) | K2: Utentes aceitam | L2: Utentes vacinados | M2: % Utentes vacinados | N2: Profissionais aceitam | O2: Profissionais vacinados | P2: Total vacinados (U+P)
A3: FCPSSSDA - Fundação da Casa do Pessoal da Segurança Social e da Saúde do Distrito de Aveiro - Centro Integrado de Aradas (ERPI) | B3: ERPI | G3: =IF($A3="","",IFERROR(F3/$D3,"")) | J3: =IF($A3="","",SUM(F3,I3)) -> 0 | M3: =IF($A3="","",IFERROR(L3/$D3,"")) | P3: =IF($A3="","",SUM(L3,O3)) -> 0
A4: Centro de Formação e Cultura da Costa do Valado (ERPI) | B4: ERPI | G4: =IF($A4="","",IFERROR(F4/$D4,"")) | J4: =IF($A4="","",SUM(F4,I4)) -> 0 | M4: =IF($A4="","",IFERROR(L4/$D4,"")) | P4: =IF($A4="","",SUM(L4,O4)) -> 0
A5: Centro Paroquial de São Bernardo (ERPI) | B5: ERPI | G5: =IF($A5="","",IFERROR(F5/$D5,"")) | J5: =IF($A5="","",SUM(F5,I5)) -> 0 | M5: =IF($A5="","",IFERROR(L5/$D5,"")) | P5: =IF($A5="","",SUM(L5,O5)) -> 0
A6: Centro Comunitário da Paróquia de S. Pedro de Aradas - Lar Paroquial Amélia Madail (ERPI) | B6: ERPI | G6: =IF($A6="","",IFERROR(F6/$D6,"")) | J6: =IF($A6="","",SUM(F6,I6)) -> 0 | M6: =IF($A6="","",IFERROR(L6/$D6,"")) | P6: =IF($A6="","",SUM(L6,O6)) -> 0
A7: Centro Social Santa Joana Princesa (ERPI) | B7: ERPI | G7: =IF($A7="","",IFERROR(F7/$D7,"")) | J7: =IF($A7="","",SUM(F7,I7)) -> 0 | M7: =IF($A7="","",IFERROR(L7/$D7,"")) | P7: =IF($A7="","",SUM(L7,O7)) -> 0
A8: Florinhas do Vouga - Casa Sacerdotal (ERPI) | B8: ERPI | G8: =IF($A8="","",IFERROR(F8/$D8,"")) | J8: =IF($A8="","",SUM(F8,I8)) -> 0 | M8: =IF($A8="","",IFERROR(L8/$D8,"")) | P8: =IF($A8="","",SUM(L8,O8)) -> 0
A9: Patronato Nossa Senhora de Fátima (ERPI) | B9: ERPI | G9: =IF($A9="","",IFERROR(F9/$D9,"")) | J9: =IF($A9="","",SUM(F9,I9)) -> 0 | M9: =IF($A9="","",IFERROR(L9/$D9,"")) | P9: =IF($A9="","",SUM(L9,O9)) -> 0
A10: Centro Comunitário da Vera Cruz (ERPI) | B10: ERPI | G10: =IF($A10="","",IFERROR(F10/$D10,"")) | J10: =IF($A10="","",SUM(F10,I10)) -> 0 | M10: =IF($A10="","",IFERROR(L10/$D10,"")) | P10: =IF($A10="","",SUM(L10,O10)) -> 0
A11: Santa Casa da Misericórdia de Aveiro - Complexo da Moita (ERPI) | B11: ERPI | G11: =IF($A11="","",IFERROR(F11/$D11,"")) | J11: =IF($A11="","",SUM(F11,I11)) -> 0 | M11: =IF($A11="","",IFERROR(L11/$D11,"")) | P11: =IF($A11="","",SUM(L11,O11)) -> 0
A12: Santa Casa da Misericórdia de Aveiro - Edifício Irmãos Rangel (ERPI) | B12: ERPI | G12: =IF($A12="","",IFERROR(F12/$D12,"")) | J12: =IF($A12="","",SUM(F12,I12)) -> 0 | M12: =IF($A12="","",IFERROR(L12/$D12,"")) | P12: =IF($A12="","",SUM(L12,O12)) -> 0
A13: Fundação CESDA - Lar Passo Senior (ERPI) | B13: ERPI | G13: =IF($A13="","",IFERROR(F13/$D13,"")) | J13: =IF($A13="","",SUM(F13,I13)) -> 0 | M13: =IF($A13="","",IFERROR(L13/$D13,"")) | P13: =IF($A13="","",SUM(L13,O13)) -> 0
A14: ASAS de Santa Joana - Associação de Solidariedade e Acção Social (ERPI) | B14: ERPI | G14: =IF($A14="","",IFERROR(F14/$D14,"")) | J14: =IF($A14="","",SUM(F14,I14)) -> 0 | M14: =IF($A14="","",IFERROR(L14/$D14,"")) | P14: =IF($A14="","",SUM(L14,O14)) -> 0
... A38: APPACDM - Lar de S. Bernardo (Lar Residencial) | B38: Lar Residencial | G38: =IF($A38="","",IFERROR(F38/$D38,"")) | J38: =IF($A38="","",SUM(F38,I38)) -> 0 | M38: =IF($A38="","",IFERROR(L38/$D38,"")) | P38: =IF($A38="","",SUM(L38,O38)) -> 0
G39: =IF($A39="","",IFERROR(F39/$D39,"")) | J39: =IF($A39="","",SUM(F39,I39)) | M39: =IF($A39="","",IFERROR(L39/$D39,"")) | P39: =IF($A39="","",SUM(L39,O39))
G40: =IF($A40="","",IFERROR(F40/$D40,"")) | J40: =IF($A40="","",SUM(F40,I40)) | M40: =IF($A40="","",IFERROR(L40/$D40,"")) | P40: =IF($A40="","",SUM(L40,O40))
G41: =IF($A41="","",IFERROR(F41/$D41,"")) | J41: =IF($A41="","",SUM(F41,I41)) | M41: =IF($A41="","",IFERROR(L41/$D41,"")) | P41: =IF($A41="","",SUM(L41,O41))
G42: =IF($A42="","",IFERROR(F42/$D42,"")) | J42: =IF($A42="","",SUM(F42,I42)) | M42: =IF($A42="","",IFERROR(L42/$D42,"")) | P42: =IF($A42="","",SUM(L42,O42))
A43: TOTAL ERPI | C43: =SUMIFS(C$3:C$42,$B$3:$B$42,"ERPI") -> 0 | D43: =SUMIFS(D$3:D$42,$B$3:$B$42,"ERPI") -> 0 | E43: =SUMIFS(E$3:E$42,$B$3:$B$42,"ERPI") -> 0 | F43: =SUMIFS(F$3:F$42,$B$3:$B$42,"ERPI") -> 0 | G43: =IFERROR(F43/D43,"") | H43: =SUMIFS(H$3:H$42,$B$3:$B$42,"ERPI") -> 0 | I43: =SUMIFS(I$3:I$42,$B$3:$B$42,"ERPI") -> 0 | J43: =SUM(F43,I43) -> 0 | K43: =SUMIFS(K$3:K$42,$B$3:$B$42,"ERPI") -> 0 | L43: =SUMIFS(L$3:L$42,$B$3:$B$42,"ERPI") -> 0 | M43: =IFERROR(L43/D43,"") | N43: =SUMIFS(N$3:N$42,$B$3:$B$42,"ERPI") -> 0 | O43: =SUMIFS(O$3:O$42,$B$3:$B$42,"ERPI") -> 0 | P43: =SUM(L43,O43) -> 0
A44: TOTAL SIMILARES | C44: =C45-C43 -> 0 | D44: =D45-D43 -> 0 | E44: =E45-E43 -> 0 | F44: =F45-F43 -> 0 | G44: =IFERROR(F44/D44,"") | H44: =H45-H43 -> 0 | I44: =I45-I43 -> 0 | J44: =SUM(F44,I44) -> 0 | K44: =K45-K43 -> 0 | L44: =L45-L43 -> 0 | M44: =IFERROR(L44/D44,"") | N44: =N45-N43 -> 0 | O44: =O45-O43 -> 0 | P44: =SUM(L44,O44) -> 0
A45: TOTAL CONCELHO | C45: =SUM(C$3:C$42) -> 0 | D45: =SUM(D$3:D$42) -> 0 | E45: =SUM(E$3:E$42) -> 0 | F45: =SUM(F$3:F$42) -> 0 | G45: =IFERROR(F45/D45,"") | H45: =SUM(H$3:H$42) -> 0 | I45: =SUM(I$3:I$42) -> 0 | J45: =SUM(F45,I45) -> 0 | K45: =SUM(K$3:K$42) -> 0 | L45: =SUM(L$3:L$42) -> 0 | M45: =IFERROR(L45/D45,"") | N45: =SUM(N$3:N$42) -> 0 | O45: =SUM(O$3:O$42) -> 0 | P45: =SUM(L45,O45) -> 0

Sheet Estarreja
E1: COVID-19 | K1: GRIPE
A2: Designação do Estabelecimento | B2: Tipologia | C2: Total Profissionais | D2: Total Utentes | E2: Utentes aceitam | F2: Utentes vacinados | G2: % Utentes vacinados | H2: Profissionais aceitam | I2: Profissionais vacinados | J2: Total vacinados (U+P) | K2: Utentes aceitam | L2: Utentes vacinados | M2: % Utentes vacinados | N2: Profissionais aceitam | O2: Profissionais vacinados | P2: Total vacinados (U+P)
A3: Centro Paroquial e Social Santa Marinha Avanca (ERPI) | B3: ERPI | G3: =IF($A3="","",IFERROR(F3/$D3,"")) | J3: =IF($A3="","",SUM(F3,I3)) -> 0 | M3: =IF($A3="","",IFERROR(L3/$D3,"")) | P3: =IF($A3="","",SUM(L3,O3)) -> 0
A4: Centro Paroquial e Social Santa Marinha Avanca (ERPI) | B4: ERPI | G4: =IF($A4="","",IFERROR(F4/$D4,"")) | J4: =IF($A4="","",SUM(F4,I4)) -> 0 | M4: =IF($A4="","",IFERROR(L4/$D4,"")) | P4: =IF($A4="","",SUM(L4,O4)) -> 0
A5: Fundação Cónego Filipe Figueiredo (ERPI) | B5: ERPI | G5: =IF($A5="","",IFERROR(F5/$D5,"")) | J5: =IF($A5="","",SUM(F5,I5)) -> 0 | M5: =IF($A5="","",IFERROR(L5/$D5,"")) | P5: =IF($A5="","",SUM(L5,O5)) -> 0
A6: Associação Quinta Rezende (ERPI) | B6: ERPI | G6: =IF($A6="","",IFERROR(F6/$D6,"")) | J6: =IF($A6="","",SUM(F6,I6)) -> 0 | M6: =IF($A6="","",IFERROR(L6/$D6,"")) | P6: =IF($A6="","",SUM(L6,O6)) -> 0
A7: Associação "Vida Nova" Lar Idosos (ERPI) | B7: ERPI | G7: =IF($A7="","",IFERROR(F7/$D7,"")) | J7: =IF($A7="","",SUM(F7,I7)) -> 0 | M7: =IF($A7="","",IFERROR(L7/$D7,"")) | P7: =IF($A7="","",SUM(L7,O7)) -> 0
A8: Associação Humanitária Salreu (ERPI) | B8: ERPI | G8: =IF($A8="","",IFERROR(F8/$D8,"")) | J8: =IF($A8="","",SUM(F8,I8)) -> 0 | M8: =IF($A8="","",IFERROR(L8/$D8,"")) | P8: =IF($A8="","",SUM(L8,O8)) -> 0
A9: Santa Casa da Misericórdia de Estarreja (ERPI) | B9: ERPI | G9: =IF($A9="","",IFERROR(F9/$D9,"")) | J9: =IF($A9="","",SUM(F9,I9)) -> 0 | M9: =IF($A9="","",IFERROR(L9/$D9,"")) | P9: =IF($A9="","",SUM(L9,O9)) -> 0
A10: Residencial Sénior Estrela Confiante (ERPI) | B10: ERPI | G10: =IF($A10="","",IFERROR(F10/$D10,"")) | J10: =IF($A10="","",SUM(F10,I10)) -> 0 | M10: =IF($A10="","",IFERROR(L10/$D10,"")) | P10: =IF($A10="","",SUM(L10,O10)) -> 0
A11: Centro Paroquial e Social Santa Marinha Avanca (CD) | B11: CD | G11: =IF($A11="","",IFERROR(F11/$D11,"")) | J11: =IF($A11="","",SUM(F11,I11)) -> 0 | M11: =IF($A11="","",IFERROR(L11/$D11,"")) | P11: =IF($A11="","",SUM(L11,O11)) -> 0
A12: Fundação Cónego Filipe Figueiredo (CD) | B12: CD | G12: =IF($A12="","",IFERROR(F12/$D12,"")) | J12: =IF($A12="","",SUM(F12,I12)) -> 0 | M12: =IF($A12="","",IFERROR(L12/$D12,"")) | P12: =IF($A12="","",SUM(L12,O12)) -> 0
A13: Associação Humanitária Salreu (CD) | B13: CD | G13: =IF($A13="","",IFERROR(F13/$D13,"")) | J13: =IF($A13="","",SUM(F13,I13)) -> 0 | M13: =IF($A13="","",IFERROR(L13/$D13,"")) | P13: =IF($A13="","",SUM(L13,O13)) -> 0
A14: Santa Casa da Misericórdia de Estarreja (CD) | B14: CD | G14: =IF($A14="","",IFERROR(F14/$D14,"")) | J14: =IF($A14="","",SUM(F14,I14)) -> 0 | M14: =IF($A14="","",IFERROR(L14/$D14,"")) | P14: =IF($A14="","",SUM(L14,O14)) -> 0
... A18: Centro Paroquial e Social Santa Marinha Avanca (UCCI) | B18: UCCI | G18: =IF($A18="","",IFERROR(F18/$D18,"")) | J18: =IF($A18="","",SUM(F18,I18)) -> 0 | M18: =IF($A18="","",IFERROR(L18/$D18,"")) | P18: =IF($A18="","",SUM(L18,O18)) -> 0
G19: =IF($A19="","",IFERROR(F19/$D19,"")) | J19: =IF($A19="","",SUM(F19,I19)) | M19: =IF($A19="","",IFERROR(L19/$D19,"")) | P19: =IF($A19="","",SUM(L19,O19))
G20: =IF($A20="","",IFERROR(F20/$D20,"")) | J20: =IF($A20="","",SUM(F20,I20)) | M20: =IF($A20="","",IFERROR(L20/$D20,"")) | P20: =IF($A20="","",SUM(L20,O20))
G21: =IF($A21="","",IFERROR(F21/$D21,"")) | J21: =IF($A21="","",SUM(F21,I21)) | M21: =IF($A21="","",IFERROR(L21/$D21,"")) | P21: =IF($A21="","",SUM(L21,O21))
G22: =IF($A22="","",IFERROR(F22/$D22,"")) | J22: =IF($A22="","",SUM(F22,I22)) | M22: =IF($A22="","",IFERROR(L22/$D22,"")) | P22: =IF($A22="","",SUM(L22,O22))
A23: TOTAL ERPI | C23: =SUMIFS(C$3:C$22,$B$3:$B$22,"ERPI") -> 0 | D23: =SUMIFS(D$3:D$22,$B$3:$B$22,"ERPI") -> 0 | E23: =SUMIFS(E$3:E$22,$B$3:$B$22,"ERPI") -> 0 | F23: =SUMIFS(F$3:F$22,$B$3:$B$22,"ERPI") -> 0 | G23: =IFERROR(F23/D23,"") | H23: =SUMIFS(H$3:H$22,$B$3:$B$22,"ERPI") -> 0 | I23: =SUMIFS(I$3:I$22,$B$3:$B$22,"ERPI") -> 0 | J23: =SUM(F23,I23) -> 0 | K23: =SUMIFS(K$3:K$22,$B$3:$B$22,"ERPI") -> 0 | L23: =SUMIFS(L$3:L$22,$B$3:$B$22,"ERPI") -> 0 | M23: =IFERROR(L23/D23,"") | N23: =SUMIFS(N$3:N$22,$B$3:$B$22,"ERPI") -> 0 | O23: =SUMIFS(O$3:O$22,$B$3:$B$22,"ERPI") -> 0 | P23: =SUM(L23,O23) -> 0
A24: TOTAL SIMILARES | C24: =C25-C23 -> 0 | D24: =D25-D23 -> 0 | E24: =E25-E23 -> 0 | F24: =F25-F23 -> 0 | G24: =IFERROR(F24/D24,"") | H24: =H25-H23 -> 0 | I24: =I25-I23 -> 0 | J24: =SUM(F24,I24) -> 0 | K24: =K25-K23 -> 0 | L24: =L25-L23 -> 0 | M24: =IFERROR(L24/D24,"") | N24: =N25-N23 -> 0 | O24: =O25-O23 -> 0 | P24: =SUM(L24,O24) -> 0
A25: TOTAL CONCELHO | C25: =SUM(C$3:C$22) -> 0 | D25: =SUM(D$3:D$22) -> 0 | E25: =SUM(E$3:E$22) -> 0 | F25: =SUM(F$3:F$22) -> 0 | G25: =IFERROR(F25/D25,"") | H25: =SUM(H$3:H$22) -> 0 | I25: =SUM(I$3:I$22) -> 0 | J25: =SUM(F25,I25) -> 0 | K25: =SUM(K$3:K$22) -> 0 | L25: =SUM(L$3:L$22) -> 0 | M25: =IFERROR(L25/D25,"") | N25: =SUM(N$3:N$22) -> 0 | O25: =SUM(O$3:O$22) -> 0 | P25: =SUM(L25,O25) -> 0

Sheet Ílhavo
E1: COVID-19 | K1: GRIPE
A2: Designação do Estabelecimento | B2: Tipologia | C2: Total Profissionais | D2: Total Utentes | E2: Utentes aceitam | F2: Utentes vacinados | G2: % Utentes vacinados | H2: Profissionais aceitam | I2: Profissionais vacinados | J2: Total vacinados (U+P) | K2: Utentes aceitam | L2: Utentes vacinados | M2: % Utentes vacinados | N2: Profissionais aceitam | O2: Profissionais vacinados | P2: Total vacinados (U+P)
A3: CASCI - Estrutura Residencial Para Pessoas Idosas 1 (ERPI 1) | B3: ERPI | G3: =IF($A3="","",IFERROR(F3/$D3,"")) | J3: =IF($A3="","",SUM(F3,I3)) -> 0 | M3: =IF($A3="","",IFERROR(L3/$D3,"")) | P3: =IF($A3="","",SUM(L3,O3)) -> 0
A4: CASCI - Estrutura Residencial Para Pessoas Idosas 2 (ERPI 2) | B4: ERPI | G4: =IF($A4="","",IFERROR(F4/$D4,"")) | J4: =IF($A4="","",SUM(F4,I4)) -> 0 | M4: =IF($A4="","",IFERROR(L4/$D4,"")) | P4: =IF($A4="","",SUM(L4,O4)) -> 0
A5: Centro Social Paroquial Nossa Senhora Nazaré (ERPI) | B5: ERPI | G5: =IF($A5="","",IFERROR(F5/$D5,"")) | J5: =IF($A5="","",SUM(F5,I5)) -> 0 | M5: =IF($A5="","",IFERROR(L5/$D5,"")) | P5: =IF($A5="","",SUM(L5,O5)) -> 0
A6: Associação Solidariedade Social Gafanha Carmo (ERPI) | B6: ERPI | G6: =IF($A6="","",IFERROR(F6/$D6,"")) | J6: =IF($A6="","",SUM(F6,I6)) -> 0 | M6: =IF($A6="","",IFERROR(L6/$D6,"")) | P6: =IF($A6="","",SUM(L6,O6)) -> 0
A7: Património dos Pobres da Freguesia de Ílhavo - Lar de São José (ERPI) | B7: ERPI | G7: =IF($A7="","",IFERROR(F7/$D7,"")) | J7: =IF($A7="","",SUM(F7,I7)) -> 0 | M7: =IF($A7="","",IFERROR(L7/$D7,"")) | P7: =IF($A7="","",SUM(L7,O7)) -> 0
A8: CASCI - Lar Residencial + CAO | B8: Lar Residencial | G8: =IF($A8="","",IFERROR(F8/$D8,"")) | J8: =IF($A8="","",SUM(F8,I8)) -> 0 | M8: =IF($A8="","",IFERROR(L8/$D8,"")) | P8: =IF($A8="","",SUM(L8,O8)) -> 0
A9: Centro Social Paroquial Nossa Senhora Nazaré (CD) | B9: CD | G9: =IF($A9="","",IFERROR(F9/$D9,"")) | J9: =IF($A9="","",SUM(F9,I9)) -> 0 | M9: =IF($A9="","",IFERROR(L9/$D9,"")) | P9: =IF($A9="","",SUM(L9,O9)) -> 0
A10: Associação Solidariedade Social Gafanha Carmo (CD) | B10: CD | G10: =IF($A10="","",IFERROR(F10/$D10,"")) | J10: =IF($A10="","",SUM(F10,I10)) -> 0 | M10: =IF($A10="","",IFERROR(L10/$D10,"")) | P10: =IF($A10="","",SUM(L10,O10)) -> 0
A11: Santa CAsa da Misericórida de Ílhavo (UCCI) | B11: UCCI | G11: =IF($A11="","",IFERROR(F11/$D11,"")) | J11: =IF($A11="","",SUM(F11,I11)) -> 0 | M11: =IF($A11="","",IFERROR(L11/$D11,"")) | P11: =IF($A11="","",SUM(L11,O11)) -> 0
G12: =IF($A12="","",IFERROR(F12/$D12,"")) | J12: =IF($A12="","",SUM(F12,I12)) | M12: =IF($A12="","",IFERROR(L12/$D12,"")) | P12: =IF($A12="","",SUM(L12,O12))
G13: =IF($A13="","",IFERROR(F13/$D13,"")) | J13: =IF($A13="","",SUM(F13,I13)) | M13: =IF($A13="","",IFERROR(L13/$D13,"")) | P13: =IF($A13="","",SUM(L13,O13))
G14: =IF($A14="","",IFERROR(F14/$D14,"")) | J14: =IF($A14="","",SUM(F14,I14)) | M14: =IF($A14="","",IFERROR(L14/$D14,"")) | P14: =IF($A14="","",SUM(L14,O14))
G15: =IF($A15="","",IFERROR(F15/$D15,"")) | J15: =IF($A15="","",SUM(F15,I15)) | M15: =IF($A15="","",IFERROR(L15/$D15,"")) | P15: =IF($A15="","",SUM(L15,O15))
A16: TOTAL ERPI | C16: =SUMIFS(C$3:C$15,$B$3:$B$15,"ERPI") -> 0 | D16: =SUMIFS(D$3:D$15,$B$3:$B$15,"ERPI") -> 0 | E16: =SUMIFS(E$3:E$15,$B$3:$B$15,"ERPI") -> 0 | F16: =SUMIFS(F$3:F$15,$B$3:$B$15,"ERPI") -> 0 | G16: =IFERROR(F16/D16,"") | H16: =SUMIFS(H$3:H$15,$B$3:$B$15,"ERPI") -> 0 | I16: =SUMIFS(I$3:I$15,$B$3:$B$15,"ERPI") -> 0 | J16: =SUM(F16,I16) -> 0 | K16: =SUMIFS(K$3:K$15,$B$3:$B$15,"ERPI") -> 0 | L16: =SUMIFS(L$3:L$15,$B$3:$B$15,"ERPI") -> 0 | M16: =IFERROR(L16/D16,"") | N16: =SUMIFS(N$3:N$15,$B$3:$B$15,"ERPI") -> 0 | O16: =SUMIFS(O$3:O$15,$B$3:$B$15,"ERPI") -> 0 | P16: =SUM(L16,O16) -> 0
A17: TOTAL SIMILARES | C17: =C18-C16 -> 0 | D17: =D18-D16 -> 0 | E17: =E18-E16 -> 0 | F17: =F18-F16 -> 0 | G17: =IFERROR(F17/D17,"") | H17: =H18-H16 -> 0 | I17: =I18-I16 -> 0 | J17: =SUM(F17,I17) -> 0 | K17: =K18-K16 -> 0 | L17: =L18-L16 -> 0 | M17: =IFERROR(L17/D17,"") | N17: =N18-N16 -> 0 | O17: =O18-O16 -> 0 | P17: =SUM(L17,O17) -> 0
A18: TOTAL CONCELHO | C18: =SUM(C$3:C$15) -> 0 | D18: =SUM(D$3:D$15) -> 0 | E18: =SUM(E$3:E$15) -> 0 | F18: =SUM(F$3:F$15) -> 0 | G18: =IFERROR(F18/D18,"") | H18: =SUM(H$3:H$15) -> 0 | I18: =SUM(I$3:I$15) -> 0 | J18: =SUM(F18,I18) -> 0 | K18: =SUM(K$3:K$15) -> 0 | L18: =SUM(L$3:L$15) -> 0 | M18: =IFERROR(L18/D18,"") | N18: =SUM(N$3:N$15) -> 0 | O18: =SUM(O$3:O$15) -> 0 | P18: =SUM(L18,O18) -> 0

Sheet Murtosa
E1: COVID-19 | K1: GRIPE
A2: Designação do Estabelecimento | B2: Tipologia | C2: Total Profissionais | D2: Total Utentes | E2: Utentes aceitam | F2: Utentes vacinados | G2: % Utentes vacinados | H2: Profissionais aceitam | I2: Profissionais vacinados | J2: Total vacinados (U+P) | K2: Utentes aceitam | L2: Utentes vacinados | M2: % Utentes vacinados | N2: Profissionais aceitam | O2: Profissionais vacinados | P2: Total vacinados (U+P)
A3: Lar Santo Estevão (ERPI) | B3: ERPI | G3: =IF($A3="","",IFERROR(F3/$D3,"")) | J3: =IF($A3="","",SUM(F3,I3)) -> 0 | M3: =IF($A3="","",IFERROR(L3/$D3,"")) | P3: =IF($A3="","",SUM(L3,O3)) -> 0
A4: Casa Repouso "Solar Nossa Terra" (ERPI) | B4: ERPI | G4: =IF($A4="","",IFERROR(F4/$D4,"")) | J4: =IF($A4="","",SUM(F4,I4)) -> 0 | M4: =IF($A4="","",IFERROR(L4/$D4,"")) | P4: =IF($A4="","",SUM(L4,O4)) -> 0
A5: Santa Casa da Misericórdia da Murtosa (ERPI) | B5: ERPI | G5: =IF($A5="","",IFERROR(F5/$D5,"")) | J5: =IF($A5="","",SUM(F5,I5)) -> 0 | M5: =IF($A5="","",IFERROR(L5/$D5,"")) | P5: =IF($A5="","",SUM(L5,O5)) -> 0
A6: Santa Casa da Misericórdia da Murtosa (CD) | B6: CD | G6: =IF($A6="","",IFERROR(F6/$D6,"")) | J6: =IF($A6="","",SUM(F6,I6)) -> 0 | M6: =IF($A6="","",IFERROR(L6/$D6,"")) | P6: =IF($A6="","",SUM(L6,O6)) -> 0
A7: Centro Social e Paroquial Bunheiro (CD) | B7: CD | G7: =IF($A7="","",IFERROR(F7/$D7,"")) | J7: =IF($A7="","",SUM(F7,I7)) -> 0 | M7: =IF($A7="","",IFERROR(L7/$D7,"")) | P7: =IF($A7="","",SUM(L7,O7)) -> 0
A8: Asfita - Associação Filantrópica Torreira (CD) | B8: CD | G8: =IF($A8="","",IFERROR(F8/$D8,"")) | J8: =IF($A8="","",SUM(F8,I8)) -> 0 | M8: =IF($A8="","",IFERROR(L8/$D8,"")) | P8: =IF($A8="","",SUM(L8,O8)) -> 0
G9: =IF($A9="","",IFERROR(F9/$D9,"")) | J9: =IF($A9="","",SUM(F9,I9)) | M9: =IF($A9="","",IFERROR(L9/$D9,"")) | P9: =IF($A9="","",SUM(L9,O9))
G10: =IF($A10="","",IFERROR(F10/$D10,"")) | J10: =IF($A10="","",SUM(F10,I10)) | M10: =IF($A10="","",IFERROR(L10/$D10,"")) | P10: =IF($A10="","",SUM(L10,O10))
G11: =IF($A11="","",IFERROR(F11/$D11,"")) | J11: =IF($A11="","",SUM(F11,I11)) | M11: =IF($A11="","",IFERROR(L11/$D11,"")) | P11: =IF($A11="","",SUM(L11,O11))
G12: =IF($A12="","",IFERROR(F12/$D12,"")) | J12: =IF($A12="","",SUM(F12,I12)) | M12: =IF($A12="","",IFERROR(L12/$D12,"")) | P12: =IF($A12="","",SUM(L12,O12))
A13: TOTAL ERPI | C13: =SUMIFS(C$3:C$12,$B$3:$B$12,"ERPI") -> 0 | D13: =SUMIFS(D$3:D$12,$B$3:$B$12,"ERPI") -> 0 | E13: =SUMIFS(E$3:E$12,$B$3:$B$12,"ERPI") -> 0 | F13: =SUMIFS(F$3:F$12,$B$3:$B$12,"ERPI") -> 0 | G13: =IFERROR(F13/D13,"") | H13: =SUMIFS(H$3:H$12,$B$3:$B$12,"ERPI") -> 0 | I13: =SUMIFS(I$3:I$12,$B$3:$B$12,"ERPI") -> 0 | J13: =SUM(F13,I13) -> 0 | K13: =SUMIFS(K$3:K$12,$B$3:$B$12,"ERPI") -> 0 | L13: =SUMIFS(L$3:L$12,$B$3:$B$12,"ERPI") -> 0 | M13: =IFERROR(L13/D13,"") | N13: =SUMIFS(N$3:N$12,$B$3:$B$12,"ERPI") -> 0 | O13: =SUMIFS(O$3:O$12,$B$3:$B$12,"ERPI") -> 0 | P13: =SUM(L13,O13) -> 0
A14: TOTAL SIMILARES | C14: =C15-C13 -> 0 | D14: =D15-D13 -> 0 | E14: =E15-E13 -> 0 | F14: =F15-F13 -> 0 | G14: =IFERROR(F14/D14,"") | H14: =H15-H13 -> 0 | I14: =I15-I13 -> 0 | J14: =SUM(F14,I14) -> 0 | K14: =K15-K13 -> 0 | L14: =L15-L13 -> 0 | M14: =IFERROR(L14/D14,"") | N14: =N15-N13 -> 0 | O14: =O15-O13 -> 0 | P14: =SUM(L14,O14) -> 0
A15: TOTAL CONCELHO | C15: =SUM(C$3:C$12) -> 0 | D15: =SUM(D$3:D$12) -> 0 | E15: =SUM(E$3:E$12) -> 0 | F15: =SUM(F$3:F$12) -> 0 | G15: =IFERROR(F15/D15,"") | H15: =SUM(H$3:H$12) -> 0 | I15: =SUM(I$3:I$12) -> 0 | J15: =SUM(F15,I15) -> 0 | K15: =SUM(K$3:K$12) -> 0 | L15: =SUM(L$3:L$12) -> 0 | M15: =IFERROR(L15/D15,"") | N15: =SUM(N$3:N$12) -> 0 | O15: =SUM(O$3:O$12) -> 0 | P15: =SUM(L15,O15) -> 0

Sheet Oliveira do Bairro
E1: COVID-19 | K1: GRIPE
A2: Designação do Estabelecimento | B2: Tipologia | C2: Total Profissionais | D2: Total Utentes | E2: Utentes aceitam | F2: Utentes vacinados | G2: % Utentes vacinados | H2: Profissionais aceitam | I2: Profissionais vacinados | J2: Total vacinados (U+P) | K2: Utentes aceitam | L2: Utentes vacinados | M2: % Utentes vacinados | N2: Profissionais aceitam | O2: Profissionais vacinados | P2: Total vacinados (U+P)
A3: Santa Casa da Misericordia de Oliveira Bairro (ERPI) | B3: ERPI | G3: =IF($A3="","",IFERROR(F3/$D3,"")) | J3: =IF($A3="","",SUM(F3,I3)) -> 0 | M3: =IF($A3="","",IFERROR(L3/$D3,"")) | P3: =IF($A3="","",SUM(L3,O3)) -> 0
A4: AMPER - Associação dos Amigos de Perrães (ERPI) | B4: ERPI | G4: =IF($A4="","",IFERROR(F4/$D4,"")) | J4: =IF($A4="","",SUM(F4,I4)) -> 0 | M4: =IF($A4="","",IFERROR(L4/$D4,"")) | P4: =IF($A4="","",SUM(L4,O4)) -> 0
A5: Sobustos (ERPI) | B5: ERPI | G5: =IF($A5="","",IFERROR(F5/$D5,"")) | J5: =IF($A5="","",SUM(F5,I5)) -> 0 | M5: =IF($A5="","",IFERROR(L5/$D5,"")) | P5: =IF($A5="","",SUM(L5,O5)) -> 0
A6: Centro Social e Paroquial de São Pedro da Palhaça (ERPI) | B6: ERPI | G6: =IF($A6="","",IFERROR(F6/$D6,"")) | J6: =IF($A6="","",SUM(F6,I6)) -> 0 | M6: =IF($A6="","",IFERROR(L6/$D6,"")) | P6: =IF($A6="","",SUM(L6,O6)) -> 0
A7: Centro Social Oiã (ERPI) | B7: ERPI | G7: =IF($A7="","",IFERROR(F7/$D7,"")) | J7: =IF($A7="","",SUM(F7,I7)) -> 0 | M7: =IF($A7="","",IFERROR(L7/$D7,"")) | P7: =IF($A7="","",SUM(L7,O7)) -> 0
A8: Recanto da Natureza (ERPI) | B8: ERPI | G8: =IF($A8="","",IFERROR(F8/$D8,"")) | J8: =IF($A8="","",SUM(F8,I8)) -> 0 | M8: =IF($A8="","",IFERROR(L8/$D8,"")) | P8: =IF($A8="","",SUM(L8,O8)) -> 0
A9: SOLSIL - Associação de Solidariedade Social do Silveiro (ERPI) | B9: ERPI | G9: =IF($A9="","",IFERROR(F9/$D9,"")) | J9: =IF($A9="","",SUM(F9,I9)) -> 0 | M9: =IF($A9="","",IFERROR(L9/$D9,"")) | P9: =IF($A9="","",SUM(L9,O9)) -> 0
A10: Lar Ricardo Jorge & Andreia (ERPI) | B10: ERPI | G10: =IF($A10="","",IFERROR(F10/$D10,"")) | J10: =IF($A10="","",SUM(F10,I10)) -> 0 | M10: =IF($A10="","",IFERROR(L10/$D10,"")) | P10: =IF($A10="","",SUM(L10,O10)) -> 0
A11: Santa Casa da Misericordia de Oliveira Bairro (CD) | B11: CD | G11: =IF($A11="","",IFERROR(F11/$D11,"")) | J11: =IF($A11="","",SUM(F11,I11)) -> 0 | M11: =IF($A11="","",IFERROR(L11/$D11,"")) | P11: =IF($A11="","",SUM(L11,O11)) -> 0
A12: Centro Social e Paroquial de São Pedro da Palhaça (CD) | B12: CD | G12: =IF($A12="","",IFERROR(F12/$D12,"")) | J12: =IF($A12="","",SUM(F12,I12)) -> 0 | M12: =IF($A12="","",IFERROR(L12/$D12,"")) | P12: =IF($A12="","",SUM(L12,O12)) -> 0
A13: Centro Social Oiã (CD) | B13: CD | G13: =IF($A13="","",IFERROR(F13/$D13,"")) | J13: =IF($A13="","",SUM(F13,I13)) -> 0 | M13: =IF($A13="","",IFERROR(L13/$D13,"")) | P13: =IF($A13="","",SUM(L13,O13)) -> 0
A14: SOLSIL - Associação de Solidariedade Social do Silveiro (CD) | B14: CD | G14: =IF($A14="","",IFERROR(F14/$D14,"")) | J14: =IF($A14="","",SUM(F14,I14)) -> 0 | M14: =IF($A14="","",IFERROR(L14/$D14,"")) | P14: =IF($A14="","",SUM(L14,O14)) -> 0
... A20: Santa Casa da Misericordia de Oliveira Bairro (UCCI) | B20: UCCI | G20: =IF($A20="","",IFERROR(F20/$D20,"")) | J20: =IF($A20="","",SUM(F20,I20)) -> 0 | M20: =IF($A20="","",IFERROR(L20/$D20,"")) | P20: =IF($A20="","",SUM(L20,O20)) -> 0
G21: =IF($A21="","",IFERROR(F21/$D21,"")) | J21: =IF($A21="","",SUM(F21,I21)) | M21: =IF($A21="","",IFERROR(L21/$D21,"")) | P21: =IF($A21="","",SUM(L21,O21))
G22: =IF($A22="","",IFERROR(F22/$D22,"")) | J22: =IF($A22="","",SUM(F22,I22)) | M22: =IF($A22="","",IFERROR(L22/$D22,"")) | P22: =IF($A22="","",SUM(L22,O22))
G23: =IF($A23="","",IFERROR(F23/$D23,"")) | J23: =IF($A23="","",SUM(F23,I23)) | M23: =IF($A23="","",IFERROR(L23/$D23,"")) | P23: =IF($A23="","",SUM(L23,O23))
G24: =IF($A24="","",IFERROR(F24/$D24,"")) | J24: =IF($A24="","",SUM(F24,I24)) | M24: =IF($A24="","",IFERROR(L24/$D24,"")) | P24: =IF($A24="","",SUM(L24,O24))
A25: TOTAL ERPI | C25: =SUMIFS(C$3:C$24,$B$3:$B$24,"ERPI") -> 0 | D25: =SUMIFS(D$3:D$24,$B$3:$B$24,"ERPI") -> 0 | E25: =SUMIFS(E$3:E$24,$B$3:$B$24,"ERPI") -> 0 | F25: =SUMIFS(F$3:F$24,$B$3:$B$24,"ERPI") -> 0 | G25: =IFERROR(F25/D25,"") | H25: =SUMIFS(H$3:H$24,$B$3:$B$24,"ERPI") -> 0 | I25: =SUMIFS(I$3:I$24,$B$3:$B$24,"ERPI") -> 0 | J25: =SUM(F25,I25) -> 0 | K25: =SUMIFS(K$3:K$24,$B$3:$B$24,"ERPI") -> 0 | L25: =SUMIFS(L$3:L$24,$B$3:$B$24,"ERPI") -> 0 | M25: =IFERROR(L25/D25,"") | N25: =SUMIFS(N$3:N$24,$B$3:$B$24,"ERPI") -> 0 | O25: =SUMIFS(O$3:O$24,$B$3:$B$24,"ERPI") -> 0 | P25: =SUM(L25,O25) -> 0
A26: TOTAL SIMILARES | C26: =C27-C25 -> 0 | D26: =D27-D25 -> 0 | E26: =E27-E25 -> 0 | F26: =F27-F25 -> 0 | G26: =IFERROR(F26/D26,"") | H26: =H27-H25 -> 0 | I26: =I27-I25 -> 0 | J26: =SUM(F26,I26) -> 0 | K26: =K27-K25 -> 0 | L26: =L27-L25 -> 0 | M26: =IFERROR(L26/D26,"") | N26: =N27-N25 -> 0 | O26: =O27-O25 -> 0 | P26: =SUM(L26,O26) -> 0
A27: TOTAL CONCELHO | C27: =SUM(C$3:C$24) -> 0 | D27: =SUM(D$3:D$24) -> 0 | E27: =SUM(E$3:E$24) -> 0 | F27: =SUM(F$3:F$24) -> 0 | G27: =IFERROR(F27/D27,"") | H27: =SUM(H$3:H$24) -> 0 | I27: =SUM(I$3:I$24) -> 0 | J27: =SUM(F27,I27) -> 0 | K27: =SUM(K$3:K$24) -> 0 | L27: =SUM(L$3:L$24) -> 0 | M27: =IFERROR(L27/D27,"") | N27: =SUM(N$3:N$24) -> 0 | O27: =SUM(O$3:O$24) -> 0 | P27: =SUM(L27,O27) -> 0

Sheet Sever do Vouga
E1: COVID-19 | K1: GRIPE
A2: Designação do Estabelecimento | B2: Tipologia | C2: Total Profissionais | D2: Total Utentes | E2: Utentes aceitam | F2: Utentes vacinados | G2: % Utentes vacinados | H2: Profissionais aceitam | I2: Profissionais vacinados | J2: Total vacinados (U+P) | K2: Utentes aceitam | L2: Utentes vacinados | M2: % Utentes vacinados | N2: Profissionais aceitam | O2: Profissionais vacinados | P2: Total vacinados (U+P)
A3: Associação Pró Cidadão Deficiente Integrado (APCDI) Nogueira (ERPI) | B3: ERPI | G3: =IF($A3="","",IFERROR(F3/$D3,"")) | J3: =IF($A3="","",SUM(F3,I3)) -> 0 | M3: =IF($A3="","",IFERROR(L3/$D3,"")) | P3: =IF($A3="","",SUM(L3,O3)) -> 0
A4: Santa Casa da Misericórdia de Sever do Vouga (ERPI) | B4: ERPI | G4: =IF($A4="","",IFERROR(F4/$D4,"")) | J4: =IF($A4="","",SUM(F4,I4)) -> 0 | M4: =IF($A4="","",IFERROR(L4/$D4,"")) | P4: =IF($A4="","",SUM(L4,O4)) -> 0
A5: Centro Social Maria Glória Almeida Pinho (ERPI) | B5: ERPI | G5: =IF($A5="","",IFERROR(F5/$D5,"")) | J5: =IF($A5="","",SUM(F5,I5)) -> 0 | M5: =IF($A5="","",IFERROR(L5/$D5,"")) | P5: =IF($A5="","",SUM(L5,O5)) -> 0
A6: Fundação Bernardo Barbosa Quadros (ERPI) | B6: ERPI | G6: =IF($A6="","",IFERROR(F6/$D6,"")) | J6: =IF($A6="","",SUM(F6,I6)) -> 0 | M6: =IF($A6="","",IFERROR(L6/$D6,"")) | P6: =IF($A6="","",SUM(L6,O6)) -> 0
A7: Associação Pró Cidadão Deficiente Integrado (APCDI) Nogueira (CD) | B7: CD | G7: =IF($A7="","",IFERROR(F7/$D7,"")) | J7: =IF($A7="","",SUM(F7,I7)) -> 0 | M7: =IF($A7="","",IFERROR(L7/$D7,"")) | P7: =IF($A7="","",SUM(L7,O7)) -> 0
A8: Santa Casa da Misericórdia de Sever do Vouga (CD) | B8: CD | G8: =IF($A8="","",IFERROR(F8/$D8,"")) | J8: =IF($A8="","",SUM(F8,I8)) -> 0 | M8: =IF($A8="","",IFERROR(L8/$D8,"")) | P8: =IF($A8="","",SUM(L8,O8)) -> 0
A9: Centro Social Maria Glória Almeida Pinho (CD) | B9: CD | G9: =IF($A9="","",IFERROR(F9/$D9,"")) | J9: =IF($A9="","",SUM(F9,I9)) -> 0 | M9: =IF($A9="","",IFERROR(L9/$D9,"")) | P9: =IF($A9="","",SUM(L9,O9)) -> 0
A10: Fundação Bernardo Barbosa Quadros (CD) | B10: CD | G10: =IF($A10="","",IFERROR(F10/$D10,"")) | J10: =IF($A10="","",SUM(F10,I10)) -> 0 | M10: =IF($A10="","",IFERROR(L10/$D10,"")) | P10: =IF($A10="","",SUM(L10,O10)) -> 0
A11: Santa Casa da Misericórdia de Sever do Vouga - Talhadas (CD) | B11: CD | G11: =IF($A11="","",IFERROR(F11/$D11,"")) | J11: =IF($A11="","",SUM(F11,I11)) -> 0 | M11: =IF($A11="","",IFERROR(L11/$D11,"")) | P11: =IF($A11="","",SUM(L11,O11)) -> 0
A12: Associação Pró Cidadão Deficiente Integrado (APCDI) Nogueira (UCCI) | B12: UCCI | G12: =IF($A12="","",IFERROR(F12/$D12,"")) | J12: =IF($A12="","",SUM(F12,I12)) -> 0 | M12: =IF($A12="","",IFERROR(L12/$D12,"")) | P12: =IF($A12="","",SUM(L12,O12)) -> 0
G13: =IF($A13="","",IFERROR(F13/$D13,"")) | J13: =IF($A13="","",SUM(F13,I13)) | M13: =IF($A13="","",IFERROR(L13/$D13,"")) | P13: =IF($A13="","",SUM(L13,O13))
G14: =IF($A14="","",IFERROR(F14/$D14,"")) | J14: =IF($A14="","",SUM(F14,I14)) | M14: =IF($A14="","",IFERROR(L14/$D14,"")) | P14: =IF($A14="","",SUM(L14,O14))
G15: =IF($A15="","",IFERROR(F15/$D15,"")) | J15: =IF($A15="","",SUM(F15,I15)) | M15: =IF($A15="","",IFERROR(L15/$D15,"")) | P15: =IF($A15="","",SUM(L15,O15))
G16: =IF($A16="","",IFERROR(F16/$D16,"")) | J16: =IF($A16="","",SUM(F16,I16)) | M16: =IF($A16="","",IFERROR(L16/$D16,"")) | P16: =IF($A16="","",SUM(L16,O16))
A17: TOTAL ERPI | C17: =SUMIFS(C$3:C$16,$B$3:$B$16,"ERPI") -> 0 | D17: =SUMIFS(D$3:D$16,$B$3:$B$16,"ERPI") -> 0 | E17: =SUMIFS(E$3:E$16,$B$3:$B$16,"ERPI") -> 0 | F17: =SUMIFS(F$3:F$16,$B$3:$B$16,"ERPI") -> 0 | G17: =IFERROR(F17/D17,"") | H17: =SUMIFS(H$3:H$16,$B$3:$B$16,"ERPI") -> 0 | I17: =SUMIFS(I$3:I$16,$B$3:$B$16,"ERPI") -> 0 | J17: =SUM(F17,I17) -> 0 | K17: =SUMIFS(K$3:K$16,$B$3:$B$16,"ERPI") -> 0 | L17: =SUMIFS(L$3:L$16,$B$3:$B$16,"ERPI") -> 0 | M17: =IFERROR(L17/D17,"") | N17: =SUMIFS(N$3:N$16,$B$3:$B$16,"ERPI") -> 0 | O17: =SUMIFS(O$3:O$16,$B$3:$B$16,"ERPI") -> 0 | P17: =SUM(L17,O17) -> 0
A18: TOTAL SIMILARES | C18: =C19-C17 -> 0 | D18: =D19-D17 -> 0 | E18: =E19-E17 -> 0 | F18: =F19-F17 -> 0 | G18: =IFERROR(F18/D18,"") | H18: =H19-H17 -> 0 | I18: =I19-I17 -> 0 | J18: =SUM(F18,I18) -> 0 | K18: =K19-K17 -> 0 | L18: =L19-L17 -> 0 | M18: =IFERROR(L18/D18,"") | N18: =N19-N17 -> 0 | O18: =O19-O17 -> 0 | P18: =SUM(L18,O18) -> 0
A19: TOTAL CONCELHO | C19: =SUM(C$3:C$16) -> 0 | D19: =SUM(D$3:D$16) -> 0 | E19: =SUM(E$3:E$16) -> 0 | F19: =SUM(F$3:F$16) -> 0 | G19: =IFERROR(F19/D19,"") | H19: =SUM(H$3:H$16) -> 0 | I19: =SUM(I$3:I$16) -> 0 | J19: =SUM(F19,I19) -> 0 | K19: =SUM(K$3:K$16) -> 0 | L19: =SUM(L$3:L$16) -> 0 | M19: =IFERROR(L19/D19,"") | N19: =SUM(N$3:N$16) -> 0 | O19: =SUM(O$3:O$16) -> 0 | P19: =SUM(L19,O19) -> 0

Sheet Vagos
E1: COVID-19 | K1: GRIPE
A2: Designação do Estabelecimento | B2: Tipologia | C2: Total Profissionais | D2: Total Utentes | E2: Utentes aceitam | F2: Utentes vacinados | G2: % Utentes vacinados | H2: Profissionais aceitam | I2: Profissionais vacinados | J2: Total vacinados (U+P) | K2: Utentes aceitam | L2: Utentes vacinados | M2: % Utentes vacinados | N2: Profissionais aceitam | O2: Profissionais vacinados | P2: Total vacinados (U+P)
A3: Centro Social e Bem Estar de Ouca - Lar de S. Martinho (ERPI) | B3: ERPI | G3: =IF($A3="","",IFERROR(F3/$D3,"")) | J3: =IF($A3="","",SUM(F3,I3)) -> 0 | M3: =IF($A3="","",IFERROR(L3/$D3,"")) | P3: =IF($A3="","",SUM(L3,O3)) -> 0
A4: Centro Comunitário do Centro Social e Bem Estar de Ouca (ERPI) | B4: ERPI | G4: =IF($A4="","",IFERROR(F4/$D4,"")) | J4: =IF($A4="","",SUM(F4,I4)) -> 0 | M4: =IF($A4="","",IFERROR(L4/$D4,"")) | P4: =IF($A4="","",SUM(L4,O4)) -> 0
A5: Santa Casa da Misericordia de Vagos (ERPI) | B5: ERPI | G5: =IF($A5="","",IFERROR(F5/$D5,"")) | J5: =IF($A5="","",SUM(F5,I5)) -> 0 | M5: =IF($A5="","",IFERROR(L5/$D5,"")) | P5: =IF($A5="","",SUM(L5,O5)) -> 0
A6: Centro de Acção Social do Covão do Lobo (ERPI) | B6: ERPI | G6: =IF($A6="","",IFERROR(F6/$D6,"")) | J6: =IF($A6="","",SUM(F6,I6)) -> 0 | M6: =IF($A6="","",IFERROR(L6/$D6,"")) | P6: =IF($A6="","",SUM(L6,O6)) -> 0
A7: Centro Social e Paroquial de Santo Antonio (ERPI) | B7: ERPI | G7: =IF($A7="","",IFERROR(F7/$D7,"")) | J7: =IF($A7="","",SUM(F7,I7)) -> 0 | M7: =IF($A7="","",IFERROR(L7/$D7,"")) | P7: =IF($A7="","",SUM(L7,O7)) -> 0
A8: Associação Boa-Hora (CD) | B8: CD | G8: =IF($A8="","",IFERROR(F8/$D8,"")) | J8: =IF($A8="","",SUM(F8,I8)) -> 0 | M8: =IF($A8="","",IFERROR(L8/$D8,"")) | P8: =IF($A8="","",SUM(L8,O8)) -> 0
A9: Associação Betel- Ponte de Vagos (CD) | B9: CD | G9: =IF($A9="","",IFERROR(F9/$D9,"")) | J9: =IF($A9="","",SUM(F9,I9)) -> 0 | M9: =IF($A9="","",IFERROR(L9/$D9,"")) | P9: =IF($A9="","",SUM(L9,O9)) -> 0
A10: Comissão de Apoio Social e Desenvolvimento Stª Catarina (CD) | B10: CD | G10: =IF($A10="","",IFERROR(F10/$D10,"")) | J10: =IF($A10="","",SUM(F10,I10)) -> 0 | M10: =IF($A10="","",IFERROR(L10/$D10,"")) | P10: =IF($A10="","",SUM(L10,O10)) -> 0
A11: Centro Social e Paroquial Calvão (CD) | B11: CD | G11: =IF($A11="","",IFERROR(F11/$D11,"")) | J11: =IF($A11="","",SUM(F11,I11)) -> 0 | M11: =IF($A11="","",IFERROR(L11/$D11,"")) | P11: =IF($A11="","",SUM(L11,O11)) -> 0
A12: Comissão de Apoio Social e Desenvolvimento Stª Catarina (Lar Residencial) | B12: Lar Residencial | G12: =IF($A12="","",IFERROR(F12/$D12,"")) | J12: =IF($A12="","",SUM(F12,I12)) -> 0 | M12: =IF($A12="","",IFERROR(L12/$D12,"")) | P12: =IF($A12="","",SUM(L12,O12)) -> 0
G13: =IF($A13="","",IFERROR(F13/$D13,"")) | J13: =IF($A13="","",SUM(F13,I13)) | M13: =IF($A13="","",IFERROR(L13/$D13,"")) | P13: =IF($A13="","",SUM(L13,O13))
G14: =IF($A14="","",IFERROR(F14/$D14,"")) | J14: =IF($A14="","",SUM(F14,I14)) | M14: =IF($A14="","",IFERROR(L14/$D14,"")) | P14: =IF($A14="","",SUM(L14,O14))
G15: =IF($A15="","",IFERROR(F15/$D15,"")) | J15: =IF($A15="","",SUM(F15,I15)) | M15: =IF($A15="","",IFERROR(L15/$D15,"")) | P15: =IF($A15="","",SUM(L15,O15))
G16: =IF($A16="","",IFERROR(F16/$D16,"")) | J16: =IF($A16="","",SUM(F16,I16)) | M16: =IF($A16="","",IFERROR(L16/$D16,"")) | P16: =IF($A16="","",SUM(L16,O16))
A17: TOTAL ERPI | C17: =SUMIFS(C$3:C$16,$B$3:$B$16,"ERPI") -> 0 | D17: =SUMIFS(D$3:D$16,$B$3:$B$16,"ERPI") -> 0 | E17: =SUMIFS(E$3:E$16,$B$3:$B$16,"ERPI") -> 0 | F17: =SUMIFS(F$3:F$16,$B$3:$B$16,"ERPI") -> 0 | G17: =IFERROR(F17/D17,"") | H17: =SUMIFS(H$3:H$16,$B$3:$B$16,"ERPI") -> 0 | I17: =SUMIFS(I$3:I$16,$B$3:$B$16,"ERPI") -> 0 | J17: =SUM(F17,I17) -> 0 | K17: =SUMIFS(K$3:K$16,$B$3:$B$16,"ERPI") -> 0 | L17: =SUMIFS(L$3:L$16,$B$3:$B$16,"ERPI") -> 0 | M17: =IFERROR(L17/D17,"") | N17: =SUMIFS(N$3:N$16,$B$3:$B$16,"ERPI") -> 0 | O17: =SUMIFS(O$3:O$16,$B$3:$B$16,"ERPI") -> 0 | P17: =SUM(L17,O17) -> 0
A18: TOTAL SIMILARES | C18: =C19-C17 -> 0 | D18: =D19-D17 -> 0 | E18: =E19-E17 -> 0 | F18: =F19-F17 -> 0 | G18: =IFERROR(F18/D18,"") | H18: =H19-H17 -> 0 | I18: =I19-I17 -> 0 | J18: =SUM(F18,I18) -> 0 | K18: =K19-K17 -> 0 | L18: =L19-L17 -> 0 | M18: =IFERROR(L18/D18,"") | N18: =N19-N17 -> 0 | O18: =O19-O17 -> 0 | P18: =SUM(L18,O18) -> 0
A19: TOTAL CONCELHO | C19: =SUM(C$3:C$16) -> 0 | D19: =SUM(D$3:D$16) -> 0 | E19: =SUM(E$3:E$16) -> 0 | F19: =SUM(F$3:F$16) -> 0 | G19: =IFERROR(F19/D19,"") | H19: =SUM(H$3:H$16) -> 0 | I19: =SUM(I$3:I$16) -> 0 | J19: =SUM(F19,I19) -> 0 | K19: =SUM(K$3:K$16) -> 0 | L19: =SUM(L$3:L$16) -> 0 | M19: =IFERROR(L19/D19,"") | N19: =SUM(N$3:N$16) -> 0 | O19: =SUM(O$3:O$16) -> 0 | P19: =SUM(L19,O19) -> 0

Sheet Núcleo Vacinação
F1: COVID-19 | M1: GRIPE
A2: Concelho | B2: Grupo | C2: Nº Estabelecimentos | D2: Total Utentes | E2: Total Profissionais | F2: Utentes aceitam | G2: Utentes vacinados | H2: % Utentes vacinados | I2: Profissionais aceitam | J2: Profissionais vacinados | K2: % Profissionais vacinados | L2: Total vacinados (U+P) | M2: Utentes aceitam | N2: Utentes vacinados | O2: % Utentes vacinados | P2: Profissionais aceitam | Q2: Profissionais vacinados | R2: % Profissionais vacinados | S2: Total vacinados (U+P)
A3: Águeda | B3: ERPI | C3: =COUNTIFS(Águeda!$B$3:$B$42,"ERPI") -> 16 | D3: =Águeda!D43 -> 0 | E3: =Águeda!C43 -> 0 | F3: =Águeda!E43 -> 0 | G3: =Águeda!F43 -> 0 | H3: =IFERROR(G3/D3,"") | I3: =Águeda!H43 -> 0 | J3: =Águeda!I43 -> 0 | K3: =IFERROR(J3/E3,"") | L3: =SUM(G3,J3) -> 0 | M3: =Águeda!K43 -> 0 | N3: =Águeda!L43 -> 0 | O3: =IFERROR(N3/D3,"") | P3: =Águeda!N43 -> 0 | Q3: =Águeda!O43 -> 0 | R3: =IFERROR(Q3/E3,"") | S3: =SUM(N3,Q3) -> 0
B4: Similares | C4: =COUNTA(Águeda!$A$3:$A$42)-COUNTIF(Águeda!$B$3:$B$42,"ERPI") -> 20 | D4: =Águeda!D44 -> 0 | E4: =Águeda!C44 -> 0 | F4: =Águeda!E44 -> 0 | G4: =Águeda!F44 -> 0 | H4: =IFERROR(G4/D4,"") | I4: =Águeda!H44 -> 0 | J4: =Águeda!I44 -> 0 | K4: =IFERROR(J4/E4,"") | L4: =SUM(G4,J4) -> 0 | M4: =Águeda!K44 -> 0 | N4: =Águeda!L44 -> 0 | O4: =IFERROR(N4/D4,"") | P4: =Águeda!N44 -> 0 | Q4: =Águeda!O44 -> 0 | R4: =IFERROR(Q4/E4,"") | S4: =SUM(N4,Q4) -> 0
B5: Total | C5: =SUM(C3:C4) -> 36 | D5: =Águeda!D45 -> 0 | E5: =Águeda!C45 -> 0 | F5: =Águeda!E45 -> 0 | G5: =Águeda!F45 -> 0 | H5: =IFERROR(G5/D5,"") | I5: =Águeda!H45 -> 0 | J5: =Águeda!I45 -> 0 | K5: =IFERROR(J5/E5,"") | L5: =SUM(G5,J5) -> 0 | M5: =Águeda!K45 -> 0 | N5: =Águeda!L45 -> 0 | O5: =IFERROR(N5/D5,"") | P5: =Águeda!N45 -> 0 | Q5: =Águeda!O45 -> 0 | R5: =IFERROR(Q5/E5,"") | S5: =SUM(N5,Q5) -> 0
A6: Albergaria-A-Velha | B6: ERPI | C6: =COUNTIFS('Albergaria-A-Velha'!$B$3:$B$20,"ERPI") -> 6 | D6: ='Albergaria-A-Velha'!D21 -> 0 | E6: ='Albergaria-A-Velha'!C21 -> 0 | F6: ='Albergaria-A-Velha'!E21 -> 0 | G6: ='Albergaria-A-Velha'!F21 -> 0 | H6: =IFERROR(G6/D6,"") | I6: ='Albergaria-A-Velha'!H21 -> 0 | J6: ='Albergaria-A-Velha'!I21 -> 0 | K6: =IFERROR(J6/E6,"") | L6: =SUM(G6,J6) -> 0 | M6: ='Albergaria-A-Velha'!K21 -> 0 | N6: ='Albergaria-A-Velha'!L21 -> 0 | O6: =IFERROR(N6/D6,"") | P6: ='Albergaria-A-Velha'!N21 -> 0 | Q6: ='Albergaria-A-Velha'!O21 -> 0 | R6: =IFERROR(Q6/E6,"") | S6: =SUM(N6,Q6) -> 0
B7: Similares | C7: =COUNTA('Albergaria-A-Velha'!$A$3:$A$20)-COUNTIF('Albergaria-A-Velha'!$B$3:$B$20,"ERPI") -> 8 | D7: ='Albergaria-A-Velha'!D22 -> 0 | E7: ='Albergaria-A-Velha'!C22 -> 0 | F7: ='Albergaria-A-Velha'!E22 -> 0 | G7: ='Albergaria-A-Velha'!F22 -> 0 | H7: =IFERROR(G7/D7,"") | I7: ='Albergaria-A-Velha'!H22 -> 0 | J7: ='Albergaria-A-Velha'!I22 -> 0 | K7: =IFERROR(J7/E7,"") | L7: =SUM(G7,J7) -> 0 | M7: ='Albergaria-A-Velha'!K22 -> 0 | N7: ='Albergaria-A-Velha'!L22 -> 0 | O7: =IFERROR(N7/D7,"") | P7: ='Albergaria-A-Velha'!N22 -> 0 | Q7: ='Albergaria-A-Velha'!O22 -> 0 | R7: =IFERROR(Q7/E7,"") | S7: =SUM(N7,Q7) -> 0
B8: Total | C8: =SUM(C6:C7) -> 14 | D8: ='Albergaria-A-Velha'!D23 -> 0 | E8: ='Albergaria-A-Velha'!C23 -> 0 | F8: ='Albergaria-A-Velha'!E23 -> 0 | G8: ='Albergaria-A-Velha'!F23 -> 0 | H8: =IFERROR(G8/D8,"") | I8: ='Albergaria-A-Velha'!H23 -> 0 | J8: ='Albergaria-A-Velha'!I23 -> 0 | K8: =IFERROR(J8/E8,"") | L8: =SUM(G8,J8) -> 0 | M8: ='Albergaria-A-Velha'!K23 -> 0 | N8: ='Albergaria-A-Velha'!L23 -> 0 | O8: =IFERROR(N8/D8,"") | P8: ='Albergaria-A-Velha'!N23 -> 0 | Q8: ='Albergaria-A-Velha'!O23 -> 0 | R8: =IFERROR(Q8/E8,"") | S8: =SUM(N8,Q8) -> 0
A9: Anadia | B9: ERPI | C9: =COUNTIFS(Anadia!$B$3:$B$32,"ERPI") -> 10 | D9: =Anadia!D33 -> 0 | E9: =Anadia!C33 -> 0 | F9: =Anadia!E33 -> 0 | G9: =Anadia!F33 -> 0 | H9: =IFERROR(G9/D9,"") | I9: =Anadia!H33 -> 0 | J9: =Anadia!I33 -> 0 | K9: =IFERROR(J9/E9,"") | L9: =SUM(G9,J9) -> 0 | M9: =Anadia!K33 -> 0 | N9: =Anadia!L33 -> 0 | O9: =IFERROR(N9/D9,"") | P9: =Anadia!N33 -> 0 | Q9: =Anadia!O33 -> 0 | R9: =IFERROR(Q9/E9,"") | S9: =SUM(N9,Q9) -> 0
B10: Similares | C10: =COUNTA(Anadia!$A$3:$A$32)-COUNTIF(Anadia!$B$3:$B$32,"ERPI") -> 16 | D10: =Anadia!D34 -> 0 | E10: =Anadia!C34 -> 0 | F10: =Anadia!E34 -> 0 | G10: =Anadia!F34 -> 0 | H10: =IFERROR(G10/D10,"") | I10: =Anadia!H34 -> 0 | J10: =Anadia!I34 -> 0 | K10: =IFERROR(J10/E10,"") | L10: =SUM(G10,J10) -> 0 | M10: =Anadia!K34 -> 0 | N10: =Anadia!L34 -> 0 | O10: =IFERROR(N10/D10,"") | P10: =Anadia!N34 -> 0 | Q10: =Anadia!O34 -> 0 | R10: =IFERROR(Q10/E10,"") | S10: =SUM(N10,Q10) -> 0
B11: Total | C11: =SUM(C9:C10) -> 26 | D11: =Anadia!D35 -> 0 | E11: =Anadia!C35 -> 0 | F11: =Anadia!E35 -> 0 | G11: =Anadia!F35 -> 0 | H11: =IFERROR(G11/D11,"") | I11: =Anadia!H35 -> 0 | J11: =Anadia!I35 -> 0 | K11: =IFERROR(J11/E11,"") | L11: =SUM(G11,J11) -> 0 | M11: =Anadia!K35 -> 0 | N11: =Anadia!L35 -> 0 | O11: =IFERROR(N11/D11,"") | P11: =Anadia!N35 -> 0 | Q11: =Anadia!O35 -> 0 | R11: =IFERROR(Q11/E11,"") | S11: =SUM(N11,Q11) -> 0
A12: Aveiro | B12: ERPI | C12: =COUNTIFS(Aveiro!$B$3:$B$42,"ERPI") -> 16 | D12: =Aveiro!D43 -> 0 | E12: =Aveiro!C43 -> 0 | F12: =Aveiro!E43 -> 0 | G12: =Aveiro!F43 -> 0 | H12: =IFERROR(G12/D12,"") | I12: =Aveiro!H43 -> 0 | J12: =Aveiro!I43 -> 0 | K12: =IFERROR(J12/E12,"") | L12: =SUM(G12,J12) -> 0 | M12: =Aveiro!K43 -> 0 | N12: =Aveiro!L43 -> 0 | O12: =IFERROR(N12/D12,"") | P12: =Aveiro!N43 -> 0 | Q12: =Aveiro!O43 -> 0 | R12: =IFERROR(Q12/E12,"") | S12: =SUM(N12,Q12) -> 0
B13: Similares | C13: =COUNTA(Aveiro!$A$3:$A$42)-COUNTIF(Aveiro!$B$3:$B$42,"ERPI") -> 20 | D13: =Aveiro!D44 -> 0 | E13: =Aveiro!C44 -> 0 | F13: =Aveiro!E44 -> 0 | G13: =Aveiro!F44 -> 0 | H13: =IFERROR(G13/D13,"") | I13: =Aveiro!H44 -> 0 | J13: =Aveiro!I44 -> 0 | K13: =IFERROR(J13/E13,"") | L13: =SUM(G13,J13) -> 0 | M13: =Aveiro!K44 -> 0 | N13: =Aveiro!L44 -> 0 | O13: =IFERROR(N13/D13,"") | P13: =Aveiro!N44 -> 0 | Q13: =Aveiro!O44 -> 0 | R13: =IFERROR(Q13/E13,"") | S13: =SUM(N13,Q13) -> 0
B14: Total | C14: =SUM(C12:C13) -> 36 | D14: =Aveiro!D45 -> 0 | E14: =Aveiro!C45 -> 0 | F14: =Aveiro!E45 -> 0 | G14: =Aveiro!F45 -> 0 | H14: =IFERROR(G14/D14,"") | I14: =Aveiro!H45 -> 0 | J14: =Aveiro!I45 -> 0 | K14: =IFERROR(J14/E14,"") | L14: =SUM(G14,J14) -> 0 | M14: =Aveiro!K45 -> 0 | N14: =Aveiro!L45 -> 0 | O14: =IFERROR(N14/D14,"") | P14: =Aveiro!N45 -> 0 | Q14: =Aveiro!O45 -> 0 | R14: =IFERROR(Q14/E14,"") | S14: =SUM(N14,Q14) -> 0
A15: Estarreja | B15: ERPI | C15: =COUNTIFS(Estarreja!$B$3:$B$22,"ERPI") -> 8 | D15: =Estarreja!D23 -> 0 | E15: =Estarreja!C23 -> 0 | F15: =Estarreja!E23 -> 0 | G15: =Estarreja!F23 -> 0 | H15: =IFERROR(G15/D15,"") | I15: =Estarreja!H23 -> 0 | J15: =Estarreja!I23 -> 0 | K15: =IFERROR(J15/E15,"") | L15: =SUM(G15,J15) -> 0 | M15: =Estarreja!K23 -> 0 | N15: =Estarreja!L23 -> 0 | O15: =IFERROR(N15/D15,"") | P15: =Estarreja!N23 -> 0 | Q15: =Estarreja!O23 -> 0 | R15: =IFERROR(Q15/E15,"") | S15: =SUM(N15,Q15) -> 0
B16: Similares | C16: =COUNTA(Estarreja!$A$3:$A$22)-COUNTIF(Estarreja!$B$3:$B$22,"ERPI") -> 8 | D16: =Estarreja!D24 -> 0 | E16: =Estarreja!C24 -> 0 | F16: =Estarreja!E24 -> 0 | G16: =Estarreja!F24 -> 0 | H16: =IFERROR(G16/D16,"") | I16: =Estarreja!H24 -> 0 | J16: =Estarreja!I24 -> 0 | K16: =IFERROR(J16/E16,"") | L16: =SUM(G16,J16) -> 0 | M16: =Estarreja!K24 -> 0 | N16: =Estarreja!L24 -> 0 | O16: =IFERROR(N16/D16,"") | P16: =Estarreja!N24 -> 0 | Q16: =Estarreja!O24 -> 0 | R16: =IFERROR(Q16/E16,"") | S16: =SUM(N16,Q16) -> 0
B17: Total | C17: =SUM(C15:C16) -> 16 | D17: =Estarreja!D25 -> 0 | E17: =Estarreja!C25 -> 0 | F17: =Estarreja!E25 -> 0 | G17: =Estarreja!F25 -> 0 | H17: =IFERROR(G17/D17,"") | I17: =Estarreja!H25 -> 0 | J17: =Estarreja!I25 -> 0 | K17: =IFERROR(J17/E17,"") | L17: =SUM(G17,J17) -> 0 | M17: =Estarreja!K25 -> 0 | N17: =Estarreja!L25 -> 0 | O17: =IFERROR(N17/D17,"") | P17: =Estarreja!N25 -> 0 | Q17: =Estarreja!O25 -> 0 | R17: =IFERROR(Q17/E17,"") | S17: =SUM(N17,Q17) -> 0
A18: Ílhavo | B18: ERPI | C18: =COUNTIFS(Ílhavo!$B$3:$B$15,"ERPI") -> 5 | D18: =Ílhavo!D16 -> 0 | E18: =Ílhavo!C16 -> 0 | F18: =Ílhavo!E16 -> 0 | G18: =Ílhavo!F16 -> 0 | H18: =IFERROR(G18/D18,"") | I18: =Ílhavo!H16 -> 0 | J18: =Ílhavo!I16 -> 0 | K18: =IFERROR(J18/E18,"") | L18: =SUM(G18,J18) -> 0 | M18: =Ílhavo!K16 -> 0 | N18: =Ílhavo!L16 -> 0 | O18: =IFERROR(N18/D18,"") | P18: =Ílhavo!N16 -> 0 | Q18: =Ílhavo!O16 -> 0 | R18: =IFERROR(Q18/E18,"") | S18: =SUM(N18,Q18) -> 0
